Workbook

Sheet Dashboard
E2: WPU Roster Dashboard
E4: Wayside Power Upgrade (BHP) | who is where, who is travelling, and NPI bookings still open
C7: ="Snapshot "&TEXT(Settings!C8,"ddd dd mmm yyyy")&" | Company: "&D9&" | Crew: "&J9&" | "&Calc!B14&" people in view"&IF(ISNUMBER(Settings!C9),""," | DATE NOT ON ROSTER")
C9: Company | D9: All | I9: Crew | J9: All | P9: Date | T9: blank = today
C11: ON SITE | H11: TRAVELLING IN | M11: TRAVELLING OUT | R11: NPI BOOKINGS PENDING | W11: ACCESS / QUALS GAPS
C12: =Calc!B2 | H12: =Calc!B3 | M12: =Calc!B4 | R12: =Calc!B15 | W12: =Calc!B16
C14: =Calc!B5&" on R&R | "&Calc!B6&" on leave" | H14: ="next 14 days: "&SUM(Calc!I2:I15)&" in" | M14: ="next 14 days: "&SUM(Calc!J2:J15)&" out" | R14: ="next 14 days | "&Calc!B17&" not yet submitted" | W14: people not fully set up (ERMS / LMS / access / quals)
C16: WHO IS WHERE - BY CAMP | P16: STATUS ON THE DAY
C39: BEDS NEEDED - WEEKLY PEAK TO DEC 2027 (WHOLE ROSTER) | P39: TRAVEL - NEXT 4 WEEKS
C61: TRAVEL - NEXT 14 DAYS | P61: NPI BOOKINGS PENDING - NEXT 14 DAYS
C62: Name | G62: Travel | L62: Date | N62: In/Out | P62: Name | T62: Roster entry | W62: Date | Y62: Status
C63: =IF(Calc!$AP2="","",INDEX('Roster Summary'!$C$31:$C$180,Calc!$AP2)) | G63: =IF(Calc!$AP2="","",INDEX(Grid!$F$3:$S$152,Calc!$AP2,Calc!$AO2+1)) | L63: =IF(Calc!$AP2="","",INDEX(Grid!$F$2:$S$2,Calc!$AO2+1)) | N63: =IF(Calc!$AP2="","",IF(INDEX(Grid!$AI$3:$AV$152,Calc!$AP2,Calc!$AO2+1)="Travel in","IN","OUT")) | P63: =IF(Calc!$AT2="","",INDEX('INPUT - Bookings'!$B$5:$B$1504,Calc!$AT2)) | T63: =IF(Calc!$AT2="","",INDEX('INPUT - Bookings'!$F$5:$F$1504,Calc!$AT2)) | W63: =IF(Calc!$AT2="","",INDEX('INPUT - Bookings'!$E$5:$E$1504,Calc!$AT2)) | Y63: =IF(Calc!$AT2="","",INDEX('INPUT - Bookings'!$G$5:$G$1504,Calc!$AT2))
C64: =IF(Calc!$AP3="","",INDEX('Roster Summary'!$C$31:$C$180,Calc!$AP3)) | G64: =IF(Calc!$AP3="","",INDEX(Grid!$F$3:$S$152,Calc!$AP3,Calc!$AO3+1)) | L64: =IF(Calc!$AP3="","",INDEX(Grid!$F$2:$S$2,Calc!$AO3+1)) | N64: =IF(Calc!$AP3="","",IF(INDEX(Grid!$AI$3:$AV$152,Calc!$AP3,Calc!$AO3+1)="Travel in","IN","OUT")) | P64: =IF(Calc!$AT3="","",INDEX('INPUT - Bookings'!$B$5:$B$1504,Calc!$AT3)) | T64: =IF(Calc!$AT3="","",INDEX('INPUT - Bookings'!$F$5:$F$1504,Calc!$AT3)) | W64: =IF(Calc!$AT3="","",INDEX('INPUT - Bookings'!$E$5:$E$1504,Calc!$AT3)) | Y64: =IF(Calc!$AT3="","",INDEX('INPUT - Bookings'!$G$5:$G$1504,Calc!$AT3))
C65: =IF(Calc!$AP4="","",INDEX('Roster Summary'!$C$31:$C$180,Calc!$AP4)) | G65: =IF(Calc!$AP4="","",INDEX(Grid!$F$3:$S$152,Calc!$AP4,Calc!$AO4+1)) | L65: =IF(Calc!$AP4="","",INDEX(Grid!$F$2:$S$2,Calc!$AO4+1)) | N65: =IF(Calc!$AP4="","",IF(INDEX(Grid!$AI$3:$AV$152,Calc!$AP4,Calc!$AO4+1)="Travel in","IN","OUT")) | P65: =IF(Calc!$AT4="","",INDEX('INPUT - Bookings'!$B$5:$B$1504,Calc!$AT4)) | T65: =IF(Calc!$AT4="","",INDEX('INPUT - Bookings'!$F$5:$F$1504,Calc!$AT4)) | W65: =IF(Calc!$AT4="","",INDEX('INPUT - Bookings'!$E$5:$E$1504,Calc!$AT4)) | Y65: =IF(Calc!$AT4="","",INDEX('INPUT - Bookings'!$G$5:$G$1504,Calc!$AT4))
C66: =IF(Calc!$AP5="","",INDEX('Roster Summary'!$C$31:$C$180,Calc!$AP5)) | G66: =IF(Calc!$AP5="","",INDEX(Grid!$F$3:$S$152,Calc!$AP5,Calc!$AO5+1)) | L66: =IF(Calc!$AP5="","",INDEX(Grid!$F$2:$S$2,Calc!$AO5+1)) | N66: =IF(Calc!$AP5="","",IF(INDEX(Grid!$AI$3:$AV$152,Calc!$AP5,Calc!$AO5+1)="Travel in","IN","OUT")) | P66: =IF(Calc!$AT5="","",INDEX('INPUT - Bookings'!$B$5:$B$1504,Calc!$AT5)) | T66: =IF(Calc!$AT5="","",INDEX('INPUT - Bookings'!$F$5:$F$1504,Calc!$AT5)) | W66: =IF(Calc!$AT5="","",INDEX('INPUT - Bookings'!$E$5:$E$1504,Calc!$AT5)) | Y66: =IF(Calc!$AT5="","",INDEX('INPUT - Bookings'!$G$5:$G$1504,Calc!$AT5))
C67: =IF(Calc!$AP6="","",INDEX('Roster Summary'!$C$31:$C$180,Calc!$AP6)) | G67: =IF(Calc!$AP6="","",INDEX(Grid!$F$3:$S$152,Calc!$AP6,Calc!$AO6+1)) | L67: =IF(Calc!$AP6="","",INDEX(Grid!$F$2:$S$2,Calc!$AO6+1)) | N67: =IF(Calc!$AP6="","",IF(INDEX(Grid!$AI$3:$AV$152,Calc!$AP6,Calc!$AO6+1)="Travel in","IN","OUT")) | P67: =IF(Calc!$AT6="","",INDEX('INPUT - Bookings'!$B$5:$B$1504,Calc!$AT6)) | T67: =IF(Calc!$AT6="","",INDEX('INPUT - Bookings'!$F$5:$F$1504,Calc!$AT6)) | W67: =IF(Calc!$AT6="","",INDEX('INPUT - Bookings'!$E$5:$E$1504,Calc!$AT6)) | Y67: =IF(Calc!$AT6="","",INDEX('INPUT - Bookings'!$G$5:$G$1504,Calc!$AT6))
C68: =IF(Calc!$AP7="","",INDEX('Roster Summary'!$C$31:$C$180,Calc!$AP7)) | G68: =IF(Calc!$AP7="","",INDEX(Grid!$F$3:$S$152,Calc!$AP7,Calc!$AO7+1)) | L68: =IF(Calc!$AP7="","",INDEX(Grid!$F$2:$S$2,Calc!$AO7+1)) | N68: =IF(Calc!$AP7="","",IF(INDEX(Grid!$AI$3:$AV$152,Calc!$AP7,Calc!$AO7+1)="Travel in","IN","OUT")) | P68: =IF(Calc!$AT7="","",INDEX('INPUT - Bookings'!$B$5:$B$1504,Calc!$AT7)) | T68: =IF(Calc!$AT7="","",INDEX('INPUT - Bookings'!$F$5:$F$1504,Calc!$AT7)) | W68: =IF(Calc!$AT7="","",INDEX('INPUT - Bookings'!$E$5:$E$1504,Calc!$AT7)) | Y68: =IF(Calc!$AT7="","",INDEX('INPUT - Bookings'!$G$5:$G$1504,Calc!$AT7))
C69: =IF(Calc!$AP8="","",INDEX('Roster Summary'!$C$31:$C$180,Calc!$AP8)) | G69: =IF(Calc!$AP8="","",INDEX(Grid!$F$3:$S$152,Calc!$AP8,Calc!$AO8+1)) | L69: =IF(Calc!$AP8="","",INDEX(Grid!$F$2:$S$2,Calc!$AO8+1)) | N69: =IF(Calc!$AP8="","",IF(INDEX(Grid!$AI$3:$AV$152,Calc!$AP8,Calc!$AO8+1)="Travel in","IN","OUT")) | P69: =IF(Calc!$AT8="","",INDEX('INPUT - Bookings'!$B$5:$B$1504,Calc!$AT8)) | T69: =IF(Calc!$AT8="","",INDEX('INPUT - Bookings'!$F$5:$F$1504,Calc!$AT8)) | W69: =IF(Calc!$AT8="","",INDEX('INPUT - Bookings'!$E$5:$E$1504,Calc!$AT8)) | Y69: =IF(Calc!$AT8="","",INDEX('INPUT - Bookings'!$G$5:$G$1504,Calc!$AT8))
C70: =IF(Calc!$AP9="","",INDEX('Roster Summary'!$C$31:$C$180,Calc!$AP9)) | G70: =IF(Calc!$AP9="","",INDEX(Grid!$F$3:$S$152,Calc!$AP9,Calc!$AO9+1)) | L70: =IF(Calc!$AP9="","",INDEX(Grid!$F$2:$S$2,Calc!$AO9+1)) | N70: =IF(Calc!$AP9="","",IF(INDEX(Grid!$AI$3:$AV$152,Calc!$AP9,Calc!$AO9+1)="Travel in","IN","OUT")) | P70: =IF(Calc!$AT9="","",INDEX('INPUT - Bookings'!$B$5:$B$1504,Calc!$AT9)) | T70: =IF(Calc!$AT9="","",INDEX('INPUT - Bookings'!$F$5:$F$1504,Calc!$AT9)) | W70: =IF(Calc!$AT9="","",INDEX('INPUT - Bookings'!$E$5:$E$1504,Calc!$AT9)) | Y70: =IF(Calc!$AT9="","",INDEX('INPUT - Bookings'!$G$5:$G$1504,Calc!$AT9))
C71: =IF(Calc!$AP10="","",INDEX('Roster Summary'!$C$31:$C$180,Calc!$AP10)) | G71: =IF(Calc!$AP10="","",INDEX(Grid!$F$3:$S$152,Calc!$AP10,Calc!$AO10+1)) | L71: =IF(Calc!$AP10="","",INDEX(Grid!$F$2:$S$2,Calc!$AO10+1)) | N71: =IF(Calc!$AP10="","",IF(INDEX(Grid!$AI$3:$AV$152,Calc!$AP10,Calc!$AO10+1)="Travel in","IN","OUT")) | P71: =IF(Calc!$AT10="","",INDEX('INPUT - Bookings'!$B$5:$B$1504,Calc!$AT10)) | T71: =IF(Calc!$AT10="","",INDEX('INPUT - Bookings'!$F$5:$F$1504,Calc!$AT10)) | W71: =IF(Calc!$AT10="","",INDEX('INPUT - Bookings'!$E$5:$E$1504,Calc!$AT10)) | Y71: =IF(Calc!$AT10="","",INDEX('INPUT - Bookings'!$G$5:$G$1504,Calc!$AT10))
C72: =IF(Calc!$AP11="","",INDEX('Roster Summary'!$C$31:$C$180,Calc!$AP11)) | G72: =IF(Calc!$AP11="","",INDEX(Grid!$F$3:$S$152,Calc!$AP11,Calc!$AO11+1)) | L72: =IF(Calc!$AP11="","",INDEX(Grid!$F$2:$S$2,Calc!$AO11+1)) | N72: =IF(Calc!$AP11="","",IF(INDEX(Grid!$AI$3:$AV$152,Calc!$AP11,Calc!$AO11+1)="Travel in","IN","OUT")) | P72: =IF(Calc!$AT11="","",INDEX('INPUT - Bookings'!$B$5:$B$1504,Calc!$AT11)) | T72: =IF(Calc!$AT11="","",INDEX('INPUT - Bookings'!$F$5:$F$1504,Calc!$AT11)) | W72: =IF(Calc!$AT11="","",INDEX('INPUT - Bookings'!$E$5:$E$1504,Calc!$AT11)) | Y72: =IF(Calc!$AT11="","",INDEX('INPUT - Bookings'!$G$5:$G$1504,Calc!$AT11))
C73: =IF(Calc!$AP12="","",INDEX('Roster Summary'!$C$31:$C$180,Calc!$AP12)) | G73: =IF(Calc!$AP12="","",INDEX(Grid!$F$3:$S$152,Calc!$AP12,Calc!$AO12+1)) | L73: =IF(Calc!$AP12="","",INDEX(Grid!$F$2:$S$2,Calc!$AO12+1)) | N73: =IF(Calc!$AP12="","",IF(INDEX(Grid!$AI$3:$AV$152,Calc!$AP12,Calc!$AO12+1)="Travel in","IN","OUT")) | P73: =IF(Calc!$AT12="","",INDEX('INPUT - Bookings'!$B$5:$B$1504,Calc!$AT12)) | T73: =IF(Calc!$AT12="","",INDEX('INPUT - Bookings'!$F$5:$F$1504,Calc!$AT12)) | W73: =IF(Calc!$AT12="","",INDEX('INPUT - Bookings'!$E$5:$E$1504,Calc!$AT12)) | Y73: =IF(Calc!$AT12="","",INDEX('INPUT - Bookings'!$G$5:$G$1504,Calc!$AT12))
C74: =IF(Calc!$AP13="","",INDEX('Roster Summary'!$C$31:$C$180,Calc!$AP13)) | G74: =IF(Calc!$AP13="","",INDEX(Grid!$F$3:$S$152,Calc!$AP13,Calc!$AO13+1)) | L74: =IF(Calc!$AP13="","",INDEX(Grid!$F$2:$S$2,Calc!$AO13+1)) | N74: =IF(Calc!$AP13="","",IF(INDEX(Grid!$AI$3:$AV$152,Calc!$AP13,Calc!$AO13+1)="Travel in","IN","OUT")) | P74: =IF(Calc!$AT13="","",INDEX('INPUT - Bookings'!$B$5:$B$1504,Calc!$AT13)) | T74: =IF(Calc!$AT13="","",INDEX('INPUT - Bookings'!$F$5:$F$1504,Calc!$AT13)) | W74: =IF(Calc!$AT13="","",INDEX('INPUT - Bookings'!$E$5:$E$1504,Calc!$AT13)) | Y74: =IF(Calc!$AT13="","",INDEX('INPUT - Bookings'!$G$5:$G$1504,Calc!$AT13))
C76: Inputs: 'INPUT - Roster' and 'INPUT - Bookings' only. Roster text is read through the code dictionary on Settings. Roster Summary, Camp Summary and Who's Where give the detail behind every number.

Sheet Roster Summary
B1: WPU Roster Summary
B2: ="Wayside Power Upgrade (BHP 2026) | Snapshot "&TEXT(Settings!$C$8,"dddd dd mmmm yyyy")&" | change the date on the Dashboard"
B4: CREW TOTALS - HEADCOUNT ON THE SNAPSHOT DATE
C5: Crew | D5: Crew size | E5: On site | F5: Travelling | G5: Off site | H5: Names on site
C6: =IFERROR(INDEX(Index!$C$2:$C$202,MATCH(1,Index!$F$2:$F$202,0)),"") | D6: =IF(C6="","",COUNTIF($E$31:$E$180,C6)) | E6: =IF(C6="","",COUNTIFS($E$31:$E$180,C6,$O$31:$O$180,"On site")) | F6: =IF(C6="","",COUNTIFS($E$31:$E$180,C6,$O$31:$O$180,"Travel in")+COUNTIFS($E$31:$E$180,C6,$O$31:$O$180,"Travel out")) | G6: =IF(C6="","",D6-E6-F6) | H6: {=IF(C6="","",_xlfn.TEXTJOIN(", ",TRUE,IF(($E$31:$E$180=C6)*($O$31:$O$180="On site"),$C$31:$C$180,"")))}
C7: =IFERROR(INDEX(Index!$C$2:$C$202,MATCH(2,Index!$F$2:$F$202,0)),"") | D7: =IF(C7="","",COUNTIF($E$31:$E$180,C7)) | E7: =IF(C7="","",COUNTIFS($E$31:$E$180,C7,$O$31:$O$180,"On site")) | F7: =IF(C7="","",COUNTIFS($E$31:$E$180,C7,$O$31:$O$180,"Travel in")+COUNTIFS($E$31:$E$180,C7,$O$31:$O$180,"Travel out")) | G7: =IF(C7="","",D7-E7-F7) | H7: {=IF(C7="","",_xlfn.TEXTJOIN(", ",TRUE,IF(($E$31:$E$180=C7)*($O$31:$O$180="On site"),$C$31:$C$180,"")))}
C8: =IFERROR(INDEX(Index!$C$2:$C$202,MATCH(3,Index!$F$2:$F$202,0)),"") | D8: =IF(C8="","",COUNTIF($E$31:$E$180,C8)) | E8: =IF(C8="","",COUNTIFS($E$31:$E$180,C8,$O$31:$O$180,"On site")) | F8: =IF(C8="","",COUNTIFS($E$31:$E$180,C8,$O$31:$O$180,"Travel in")+COUNTIFS($E$31:$E$180,C8,$O$31:$O$180,"Travel out")) | G8: =IF(C8="","",D8-E8-F8) | H8: {=IF(C8="","",_xlfn.TEXTJOIN(", ",TRUE,IF(($E$31:$E$180=C8)*($O$31:$O$180="On site"),$C$31:$C$180,"")))}
C9: =IFERROR(INDEX(Index!$C$2:$C$202,MATCH(4,Index!$F$2:$F$202,0)),"") | D9: =IF(C9="","",COUNTIF($E$31:$E$180,C9)) | E9: =IF(C9="","",COUNTIFS($E$31:$E$180,C9,$O$31:$O$180,"On site")) | F9: =IF(C9="","",COUNTIFS($E$31:$E$180,C9,$O$31:$O$180,"Travel in")+COUNTIFS($E$31:$E$180,C9,$O$31:$O$180,"Travel out")) | G9: =IF(C9="","",D9-E9-F9) | H9: {=IF(C9="","",_xlfn.TEXTJOIN(", ",TRUE,IF(($E$31:$E$180=C9)*($O$31:$O$180="On site"),$C$31:$C$180,"")))}
C10: =IFERROR(INDEX(Index!$C$2:$C$202,MATCH(5,Index!$F$2:$F$202,0)),"") | D10: =IF(C10="","",COUNTIF($E$31:$E$180,C10)) | E10: =IF(C10="","",COUNTIFS($E$31:$E$180,C10,$O$31:$O$180,"On site")) | F10: =IF(C10="","",COUNTIFS($E$31:$E$180,C10,$O$31:$O$180,"Travel in")+COUNTIFS($E$31:$E$180,C10,$O$31:$O$180,"Travel out")) | G10: =IF(C10="","",D10-E10-F10) | H10: {=IF(C10="","",_xlfn.TEXTJOIN(", ",TRUE,IF(($E$31:$E$180=C10)*($O$31:$O$180="On site"),$C$31:$C$180,"")))}
C11: =IFERROR(INDEX(Index!$C$2:$C$202,MATCH(6,Index!$F$2:$F$202,0)),"") | D11: =IF(C11="","",COUNTIF($E$31:$E$180,C11)) | E11: =IF(C11="","",COUNTIFS($E$31:$E$180,C11,$O$31:$O$180,"On site")) | F11: =IF(C11="","",COUNTIFS($E$31:$E$180,C11,$O$31:$O$180,"Travel in")+COUNTIFS($E$31:$E$180,C11,$O$31:$O$180,"Travel out")) | G11: =IF(C11="","",D11-E11-F11) | H11: {=IF(C11="","",_xlfn.TEXTJOIN(", ",TRUE,IF(($E$31:$E$180=C11)*($O$31:$O$180="On site"),$C$31:$C$180,"")))}
C12: =IFERROR(INDEX(Index!$C$2:$C$202,MATCH(7,Index!$F$2:$F$202,0)),"") | D12: =IF(C12="","",COUNTIF($E$31:$E$180,C12)) | E12: =IF(C12="","",COUNTIFS($E$31:$E$180,C12,$O$31:$O$180,"On site")) | F12: =IF(C12="","",COUNTIFS($E$31:$E$180,C12,$O$31:$O$180,"Travel in")+COUNTIFS($E$31:$E$180,C12,$O$31:$O$180,"Travel out")) | G12: =IF(C12="","",D12-E12-F12) | H12: {=IF(C12="","",_xlfn.TEXTJOIN(", ",TRUE,IF(($E$31:$E$180=C12)*($O$31:$O$180="On site"),$C$31:$C$180,"")))}
C13: =IFERROR(INDEX(Index!$C$2:$C$202,MATCH(8,Index!$F$2:$F$202,0)),"") | D13: =IF(C13="","",COUNTIF($E$31:$E$180,C13)) | E13: =IF(C13="","",COUNTIFS($E$31:$E$180,C13,$O$31:$O$180,"On site")) | F13: =IF(C13="","",COUNTIFS($E$31:$E$180,C13,$O$31:$O$180,"Travel in")+COUNTIFS($E$31:$E$180,C13,$O$31:$O$180,"Travel out")) | G13: =IF(C13="","",D13-E13-F13) | H13: {=IF(C13="","",_xlfn.TEXTJOIN(", ",TRUE,IF(($E$31:$E$180=C13)*($O$31:$O$180="On site"),$C$31:$C$180,"")))}
C14: =IFERROR(INDEX(Index!$C$2:$C$202,MATCH(9,Index!$F$2:$F$202,0)),"") | D14: =IF(C14="","",COUNTIF($E$31:$E$180,C14)) | E14: =IF(C14="","",COUNTIFS($E$31:$E$180,C14,$O$31:$O$180,"On site")) | F14: =IF(C14="","",COUNTIFS($E$31:$E$180,C14,$O$31:$O$180,"Travel in")+COUNTIFS($E$31:$E$180,C14,$O$31:$O$180,"Travel out")) | G14: =IF(C14="","",D14-E14-F14) | H14: {=IF(C14="","",_xlfn.TEXTJOIN(", ",TRUE,IF(($E$31:$E$180=C14)*($O$31:$O$180="On site"),$C$31:$C$180,"")))}
C15: =IFERROR(INDEX(Index!$C$2:$C$202,MATCH(10,Index!$F$2:$F$202,0)),"") | D15: =IF(C15="","",COUNTIF($E$31:$E$180,C15)) | E15: =IF(C15="","",COUNTIFS($E$31:$E$180,C15,$O$31:$O$180,"On site")) | F15: =IF(C15="","",COUNTIFS($E$31:$E$180,C15,$O$31:$O$180,"Travel in")+COUNTIFS($E$31:$E$180,C15,$O$31:$O$180,"Travel out")) | G15: =IF(C15="","",D15-E15-F15) | H15: {=IF(C15="","",_xlfn.TEXTJOIN(", ",TRUE,IF(($E$31:$E$180=C15)*($O$31:$O$180="On site"),$C$31:$C$180,"")))}
C16: =IFERROR(INDEX(Index!$C$2:$C$202,MATCH(11,Index!$F$2:$F$202,0)),"") | D16: =IF(C16="","",COUNTIF($E$31:$E$180,C16)) | E16: =IF(C16="","",COUNTIFS($E$31:$E$180,C16,$O$31:$O$180,"On site")) | F16: =IF(C16="","",COUNTIFS($E$31:$E$180,C16,$O$31:$O$180,"Travel in")+COUNTIFS($E$31:$E$180,C16,$O$31:$O$180,"Travel out")) | G16: =IF(C16="","",D16-E16-F16) | H16: {=IF(C16="","",_xlfn.TEXTJOIN(", ",TRUE,IF(($E$31:$E$180=C16)*($O$31:$O$180="On site"),$C$31:$C$180,"")))}
C17: =IFERROR(INDEX(Index!$C$2:$C$202,MATCH(12,Index!$F$2:$F$202,0)),"") | D17: =IF(C17="","",COUNTIF($E$31:$E$180,C17)) | E17: =IF(C17="","",COUNTIFS($E$31:$E$180,C17,$O$31:$O$180,"On site")) | F17: =IF(C17="","",COUNTIFS($E$31:$E$180,C17,$O$31:$O$180,"Travel in")+COUNTIFS($E$31:$E$180,C17,$O$31:$O$180,"Travel out")) | G17: =IF(C17="","",D17-E17-F17) | H17: {=IF(C17="","",_xlfn.TEXTJOIN(", ",TRUE,IF(($E$31:$E$180=C17)*($O$31:$O$180="On site"),$C$31:$C$180,"")))}
C18: =IFERROR(INDEX(Index!$C$2:$C$202,MATCH(13,Index!$F$2:$F$202,0)),"") | D18: =IF(C18="","",COUNTIF($E$31:$E$180,C18)) | E18: =IF(C18="","",COUNTIFS($E$31:$E$180,C18,$O$31:$O$180,"On site")) | F18: =IF(C18="","",COUNTIFS($E$31:$E$180,C18,$O$31:$O$180,"Travel in")+COUNTIFS($E$31:$E$180,C18,$O$31:$O$180,"Travel out")) | G18: =IF(C18="","",D18-E18-F18) | H18: {=IF(C18="","",_xlfn.TEXTJOIN(", ",TRUE,IF(($E$31:$E$180=C18)*($O$31:$O$180="On site"),$C$31:$C$180,"")))}
C19: =IFERROR(INDEX(Index!$C$2:$C$202,MATCH(14,Index!$F$2:$F$202,0)),"") | D19: =IF(C19="","",COUNTIF($E$31:$E$180,C19)) | E19: =IF(C19="","",COUNTIFS($E$31:$E$180,C19,$O$31:$O$180,"On site")) | F19: =IF(C19="","",COUNTIFS($E$31:$E$180,C19,$O$31:$O$180,"Travel in")+COUNTIFS($E$31:$E$180,C19,$O$31:$O$180,"Travel out")) | G19: =IF(C19="","",D19-E19-F19) | H19: {=IF(C19="","",_xlfn.TEXTJOIN(", ",TRUE,IF(($E$31:$E$180=C19)*($O$31:$O$180="On site"),$C$31:$C$180,"")))}
C20: =IFERROR(INDEX(Index!$C$2:$C$202,MATCH(15,Index!$F$2:$F$202,0)),"") | D20: =IF(C20="","",COUNTIF($E$31:$E$180,C20)) | E20: =IF(C20="","",COUNTIFS($E$31:$E$180,C20,$O$31:$O$180,"On site")) | F20: =IF(C20="","",COUNTIFS($E$31:$E$180,C20,$O$31:$O$180,"Travel in")+COUNTIFS($E$31:$E$180,C20,$O$31:$O$180,"Travel out")) | G20: =IF(C20="","",D20-E20-F20) | H20: {=IF(C20="","",_xlfn.TEXTJOIN(", ",TRUE,IF(($E$31:$E$180=C20)*($O$31:$O$180="On site"),$C$31:$C$180,"")))}
C21: =IFERROR(INDEX(Index!$C$2:$C$202,MATCH(16,Index!$F$2:$F$202,0)),"") | D21: =IF(C21="","",COUNTIF($E$31:$E$180,C21)) | E21: =IF(C21="","",COUNTIFS($E$31:$E$180,C21,$O$31:$O$180,"On site")) | F21: =IF(C21="","",COUNTIFS($E$31:$E$180,C21,$O$31:$O$180,"Travel in")+COUNTIFS($E$31:$E$180,C21,$O$31:$O$180,"Travel out")) | G21: =IF(C21="","",D21-E21-F21) | H21: {=IF(C21="","",_xlfn.TEXTJOIN(", ",TRUE,IF(($E$31:$E$180=C21)*($O$31:$O$180="On site"),$C$31:$C$180,"")))}
C22: =IFERROR(INDEX(Index!$C$2:$C$202,MATCH(17,Index!$F$2:$F$202,0)),"") | D22: =IF(C22="","",COUNTIF($E$31:$E$180,C22)) | E22: =IF(C22="","",COUNTIFS($E$31:$E$180,C22,$O$31:$O$180,"On site")) | F22: =IF(C22="","",COUNTIFS($E$31:$E$180,C22,$O$31:$O$180,"Travel in")+COUNTIFS($E$31:$E$180,C22,$O$31:$O$180,"Travel out")) | G22: =IF(C22="","",D22-E22-F22) | H22: {=IF(C22="","",_xlfn.TEXTJOIN(", ",TRUE,IF(($E$31:$E$180=C22)*($O$31:$O$180="On site"),$C$31:$C$180,"")))}
C23: =IFERROR(INDEX(Index!$C$2:$C$202,MATCH(18,Index!$F$2:$F$202,0)),"") | D23: =IF(C23="","",COUNTIF($E$31:$E$180,C23)) | E23: =IF(C23="","",COUNTIFS($E$31:$E$180,C23,$O$31:$O$180,"On site")) | F23: =IF(C23="","",COUNTIFS($E$31:$E$180,C23,$O$31:$O$180,"Travel in")+COUNTIFS($E$31:$E$180,C23,$O$31:$O$180,"Travel out")) | G23: =IF(C23="","",D23-E23-F23) | H23: {=IF(C23="","",_xlfn.TEXTJOIN(", ",TRUE,IF(($E$31:$E$180=C23)*($O$31:$O$180="On site"),$C$31:$C$180,"")))}
C24: =IFERROR(INDEX(Index!$C$2:$C$202,MATCH(19,Index!$F$2:$F$202,0)),"") | D24: =IF(C24="","",COUNTIF($E$31:$E$180,C24)) | E24: =IF(C24="","",COUNTIFS($E$31:$E$180,C24,$O$31:$O$180,"On site")) | F24: =IF(C24="","",COUNTIFS($E$31:$E$180,C24,$O$31:$O$180,"Travel in")+COUNTIFS($E$31:$E$180,C24,$O$31:$O$180,"Travel out")) | G24: =IF(C24="","",D24-E24-F24) | H24: {=IF(C24="","",_xlfn.TEXTJOIN(", ",TRUE,IF(($E$31:$E$180=C24)*($O$31:$O$180="On site"),$C$31:$C$180,"")))}
C25: =IFERROR(INDEX(Index!$C$2:$C$202,MATCH(20,Index!$F$2:$F$202,0)),"") | D25: =IF(C25="","",COUNTIF($E$31:$E$180,C25)) | E25: =IF(C25="","",COUNTIFS($E$31:$E$180,C25,$O$31:$O$180,"On site")) | F25: =IF(C25="","",COUNTIFS($E$31:$E$180,C25,$O$31:$O$180,"Travel in")+COUNTIFS($E$31:$E$180,C25,$O$31:$O$180,"Travel out")) | G25: =IF(C25="","",D25-E25-F25) | H25: {=IF(C25="","",_xlfn.TEXTJOIN(", ",TRUE,IF(($E$31:$E$180=C25)*($O$31:$O$180="On site"),$C$31:$C$180,"")))}
C26: TOTAL WORKFORCE | D26: =SUMIF($C$6:$C$25,"<>*demob*",D6:D25) | E26: =SUMIF($C$6:$C$25,"<>*demob*",E6:E25) | F26: =SUMIF($C$6:$C$25,"<>*demob*",F6:F25) | G26: =SUMIF($C$6:$C$25,"<>*demob*",G6:G25) | H26: (excludes Demobilised)
B28: INDIVIDUAL STATUS - SNAPSHOT DATE
B30: # | C30: Name | D30: Company | E30: Crew | F30: Role | G30: POH | H30: Roster | I30: Mobile | J30: ERMS profile | K30: LMS inductions | L30: Site access | M30: Quals status | N30: Today - roster entry | O30: Today - status | P30: Today - camp | Q30: Next travel date | R30: Next travel | S30: BHP access active | T30: Access / quals gap | U30: In filter
B31: =IF(Grid!$B3="","",1) | C31: =IF(Grid!$B3="","",TRIM(INDEX('INPUT - Roster'!$F$1:$F$206,Grid!$B3)&"")) | D31: =IF(Grid!$B3="","",TRIM(INDEX('INPUT - Roster'!$C$1:$C$206,Grid!$B3)&"")) | E31: =IF(Grid!$B3="","",INDEX(Index!$C$2:$C$202,MATCH(Grid!$B3,Index!$A$2:$A$202,0))) | F31: =IF(Grid!$B3="","",TRIM(INDEX('INPUT - Roster'!$H$1:$H$206,Grid!$B3)&"")) | G31: =IF(Grid!$B3="","",TRIM(INDEX('INPUT - Roster'!$G$1:$G$206,Grid!$B3)&"")) | H31: =IF(Grid!$B3="","",TRIM(INDEX('INPUT - Roster'!$R$1:$R$206,Grid!$B3)&"")) | I31: =IF(Grid!$B3="","",TRIM(INDEX('INPUT - Roster'!$O$1:$O$206,Grid!$B3)&"")) | J31: =IF(Grid!$B3="","",TRIM(INDEX('INPUT - Roster'!$J$1:$J$206,Grid!$B3)&"")) | K31: =IF(Grid!$B3="","",TRIM(INDEX('INPUT - Roster'!$K$1:$K$206,Grid!$B3)&"")) | L31: =IF(Grid!$B3="","",TRIM(INDEX('INPUT - Roster'!$L$1:$L$206,Grid!$B3)&"")) | M31: =IF(Grid!$B3="","",TRIM(INDEX('INPUT - Roster'!$M$1:$M$206,Grid!$B3)&"")) | N31: =Grid!F3 | O31: =Grid!AI3 | P31: =Grid!BL3 | Q31: =IF(Grid!$D3="","",INDEX(Grid!$F$2:$AG$2,Grid!$D3)) | R31: =IF(Grid!$D3="","",INDEX(Grid!$F3:$AG3,Grid!$D3)) | S31: =IF(Grid!$B3="","",IFERROR(TRIM(INDEX('BHP Site Access'!$G$3:$G$104,MATCH(LOWER(TRIM(INDEX('INPUT - Roster'!$D$1:$D$206,Grid!$B3)&"")&"|"&TRIM(INDEX('INPUT - Roster'!$E$1:$E$206,Grid!$B3)&"")),Calc!$AX$3:$AX$104,0))&""),"Not listed")) | T31: =IF(OR(Grid!$B3="",ISNUMBER(SEARCH("demob",E31))),"",IF(AND(UPPER(TRIM(J31&""))="YES",UPPER(TRIM(K31&""))="YES",UPPER(TRIM(L31&""))="YES",LEFT(UPPER(M31),14)="QUALS COMPLETE"),"","GAP")) | U31: =IF(Grid!$B3="",0,IF(AND(OR(Dashboard!$D$9="All",D31=Dashboard!$D$9),OR(Dashboard!$J$9="All",E31=Dashboard!$J$9)),1,0))
B32: =IF(Grid!$B4="","",2) | C32: =IF(Grid!$B4="","",TRIM(INDEX('INPUT - Roster'!$F$1:$F$206,Grid!$B4)&"")) | D32: =IF(Grid!$B4="","",TRIM(INDEX('INPUT - Roster'!$C$1:$C$206,Grid!$B4)&"")) | E32: =IF(Grid!$B4="","",INDEX(Index!$C$2:$C$202,MATCH(Grid!$B4,Index!$A$2:$A$202,0))) | F32: =IF(Grid!$B4="","",TRIM(INDEX('INPUT - Roster'!$H$1:$H$206,Grid!$B4)&"")) | G32: =IF(Grid!$B4="","",TRIM(INDEX('INPUT - Roster'!$G$1:$G$206,Grid!$B4)&"")) | H32: =IF(Grid!$B4="","",TRIM(INDEX('INPUT - Roster'!$R$1:$R$206,Grid!$B4)&"")) | I32: =IF(Grid!$B4="","",TRIM(INDEX('INPUT - Roster'!$O$1:$O$206,Grid!$B4)&"")) | J32: =IF(Grid!$B4="","",TRIM(INDEX('INPUT - Roster'!$J$1:$J$206,Grid!$B4)&"")) | K32: =IF(Grid!$B4="","",TRIM(INDEX('INPUT - Roster'!$K$1:$K$206,Grid!$B4)&"")) | L32: =IF(Grid!$B4="","",TRIM(INDEX('INPUT - Roster'!$L$1:$L$206,Grid!$B4)&"")) | M32: =IF(Grid!$B4="","",TRIM(INDEX('INPUT - Roster'!$M$1:$M$206,Grid!$B4)&"")) | N32: =Grid!F4 | O32: =Grid!AI4 | P32: =Grid!BL4 | Q32: =IF(Grid!$D4="","",INDEX(Grid!$F$2:$AG$2,Grid!$D4)) | R32: =IF(Grid!$D4="","",INDEX(Grid!$F4:$AG4,Grid!$D4)) | S32: =IF(Grid!$B4="","",IFERROR(TRIM(INDEX('BHP Site Access'!$G$3:$G$104,MATCH(LOWER(TRIM(INDEX('INPUT - Roster'!$D$1:$D$206,Grid!$B4)&"")&"|"&TRIM(INDEX('INPUT - Roster'!$E$1:$E$206,Grid!$B4)&"")),Calc!$AX$3:$AX$104,0))&""),"Not listed")) | T32: =IF(OR(Grid!$B4="",ISNUMBER(SEARCH("demob",E32))),"",IF(AND(UPPER(TRIM(J32&""))="YES",UPPER(TRIM(K32&""))="YES",UPPER(TRIM(L32&""))="YES",LEFT(UPPER(M32),14)="QUALS COMPLETE"),"","GAP")) | U32: =IF(Grid!$B4="",0,IF(AND(OR(Dashboard!$D$9="All",D32=Dashboard!$D$9),OR(Dashboard!$J$9="All",E32=Dashboard!$J$9)),1,0))
B33: =IF(Grid!$B5="","",3) | C33: =IF(Grid!$B5="","",TRIM(INDEX('INPUT - Roster'!$F$1:$F$206,Grid!$B5)&"")) | D33: =IF(Grid!$B5="","",TRIM(INDEX('INPUT - Roster'!$C$1:$C$206,Grid!$B5)&"")) | E33: =IF(Grid!$B5="","",INDEX(Index!$C$2:$C$202,MATCH(Grid!$B5,Index!$A$2:$A$202,0))) | F33: =IF(Grid!$B5="","",TRIM(INDEX('INPUT - Roster'!$H$1:$H$206,Grid!$B5)&"")) | G33: =IF(Grid!$B5="","",TRIM(INDEX('INPUT - Roster'!$G$1:$G$206,Grid!$B5)&"")) | H33: =IF(Grid!$B5="","",TRIM(INDEX('INPUT - Roster'!$R$1:$R$206,Grid!$B5)&"")) | I33: =IF(Grid!$B5="","",TRIM(INDEX('INPUT - Roster'!$O$1:$O$206,Grid!$B5)&"")) | J33: =IF(Grid!$B5="","",TRIM(INDEX('INPUT - Roster'!$J$1:$J$206,Grid!$B5)&"")) | K33: =IF(Grid!$B5="","",TRIM(INDEX('INPUT - Roster'!$K$1:$K$206,Grid!$B5)&"")) | L33: =IF(Grid!$B5="","",TRIM(INDEX('INPUT - Roster'!$L$1:$L$206,Grid!$B5)&"")) | M33: =IF(Grid!$B5="","",TRIM(INDEX('INPUT - Roster'!$M$1:$M$206,Grid!$B5)&"")) | N33: =Grid!F5 | O33: =Grid!AI5 | P33: =Grid!BL5 | Q33: =IF(Grid!$D5="","",INDEX(Grid!$F$2:$AG$2,Grid!$D5)) | R33: =IF(Grid!$D5="","",INDEX(Grid!$F5:$AG5,Grid!$D5)) | S33: =IF(Grid!$B5="","",IFERROR(TRIM(INDEX('BHP Site Access'!$G$3:$G$104,MATCH(LOWER(TRIM(INDEX('INPUT - Roster'!$D$1:$D$206,Grid!$B5)&"")&"|"&TRIM(INDEX('INPUT - Roster'!$E$1:$E$206,Grid!$B5)&"")),Calc!$AX$3:$AX$104,0))&""),"Not listed")) | T33: =IF(OR(Grid!$B5="",ISNUMBER(SEARCH("demob",E33))),"",IF(AND(UPPER(TRIM(J33&""))="YES",UPPER(TRIM(K33&""))="YES",UPPER(TRIM(L33&""))="YES",LEFT(UPPER(M33),14)="QUALS COMPLETE"),"","GAP")) | U33: =IF(Grid!$B5="",0,IF(AND(OR(Dashboard!$D$9="All",D33=Dashboard!$D$9),OR(Dashboard!$J$9="All",E33=Dashboard!$J$9)),1,0))
B34: =IF(Grid!$B6="","",4) | C34: =IF(Grid!$B6="","",TRIM(INDEX('INPUT - Roster'!$F$1:$F$206,Grid!$B6)&"")) | D34: =IF(Grid!$B6="","",TRIM(INDEX('INPUT - Roster'!$C$1:$C$206,Grid!$B6)&"")) | E34: =IF(Grid!$B6="","",INDEX(Index!$C$2:$C$202,MATCH(Grid!$B6,Index!$A$2:$A$202,0))) | F34: =IF(Grid!$B6="","",TRIM(INDEX('INPUT - Roster'!$H$1:$H$206,Grid!$B6)&"")) | G34: =IF(Grid!$B6="","",TRIM(INDEX('INPUT - Roster'!$G$1:$G$206,Grid!$B6)&"")) | H34: =IF(Grid!$B6="","",TRIM(INDEX('INPUT - Roster'!$R$1:$R$206,Grid!$B6)&"")) | I34: =IF(Grid!$B6="","",TRIM(INDEX('INPUT - Roster'!$O$1:$O$206,Grid!$B6)&"")) | J34: =IF(Grid!$B6="","",TRIM(INDEX('INPUT - Roster'!$J$1:$J$206,Grid!$B6)&"")) | K34: =IF(Grid!$B6="","",TRIM(INDEX('INPUT - Roster'!$K$1:$K$206,Grid!$B6)&"")) | L34: =IF(Grid!$B6="","",TRIM(INDEX('INPUT - Roster'!$L$1:$L$206,Grid!$B6)&"")) | M34: =IF(Grid!$B6="","",TRIM(INDEX('INPUT - Roster'!$M$1:$M$206,Grid!$B6)&"")) | N34: =Grid!F6 | O34: =Grid!AI6 | P34: =Grid!BL6 | Q34: =IF(Grid!$D6="","",INDEX(Grid!$F$2:$AG$2,Grid!$D6)) | R34: =IF(Grid!$D6="","",INDEX(Grid!$F6:$AG6,Grid!$D6)) | S34: =IF(Grid!$B6="","",IFERROR(TRIM(INDEX('BHP Site Access'!$G$3:$G$104,MATCH(LOWER(TRIM(INDEX('INPUT - Roster'!$D$1:$D$206,Grid!$B6)&"")&"|"&TRIM(INDEX('INPUT - Roster'!$E$1:$E$206,Grid!$B6)&"")),Calc!$AX$3:$AX$104,0))&""),"Not listed")) | T34: =IF(OR(Grid!$B6="",ISNUMBER(SEARCH("demob",E34))),"",IF(AND(UPPER(TRIM(J34&""))="YES",UPPER(TRIM(K34&""))="YES",UPPER(TRIM(L34&""))="YES",LEFT(UPPER(M34),14)="QUALS COMPLETE"),"","GAP")) | U34: =IF(Grid!$B6="",0,IF(AND(OR(Dashboard!$D$9="All",D34=Dashboard!$D$9),OR(Dashboard!$J$9="All",E34=Dashboard!$J$9)),1,0))
B35: =IF(Grid!$B7="","",5) | C35: =IF(Grid!$B7="","",TRIM(INDEX('INPUT - Roster'!$F$1:$F$206,Grid!$B7)&"")) | D35: =IF(Grid!$B7="","",TRIM(INDEX('INPUT - Roster'!$C$1:$C$206,Grid!$B7)&"")) | E35: =IF(Grid!$B7="","",INDEX(Index!$C$2:$C$202,MATCH(Grid!$B7,Index!$A$2:$A$202,0))) | F35: =IF(Grid!$B7="","",TRIM(INDEX('INPUT - Roster'!$H$1:$H$206,Grid!$B7)&"")) | G35: =IF(Grid!$B7="","",TRIM(INDEX('INPUT - Roster'!$G$1:$G$206,Grid!$B7)&"")) | H35: =IF(Grid!$B7="","",TRIM(INDEX('INPUT - Roster'!$R$1:$R$206,Grid!$B7)&"")) | I35: =IF(Grid!$B7="","",TRIM(INDEX('INPUT - Roster'!$O$1:$O$206,Grid!$B7)&"")) | J35: =IF(Grid!$B7="","",TRIM(INDEX('INPUT - Roster'!$J$1:$J$206,Grid!$B7)&"")) | K35: =IF(Grid!$B7="","",TRIM(INDEX('INPUT - Roster'!$K$1:$K$206,Grid!$B7)&"")) | L35: =IF(Grid!$B7="","",TRIM(INDEX('INPUT - Roster'!$L$1:$L$206,Grid!$B7)&"")) | M35: =IF(Grid!$B7="","",TRIM(INDEX('INPUT - Roster'!$M$1:$M$206,Grid!$B7)&"")) | N35: =Grid!F7 | O35: =Grid!AI7 | P35: =Grid!BL7 | Q35: =IF(Grid!$D7="","",INDEX(Grid!$F$2:$AG$2,Grid!$D7)) | R35: =IF(Grid!$D7="","",INDEX(Grid!$F7:$AG7,Grid!$D7)) | S35: =IF(Grid!$B7="","",IFERROR(TRIM(INDEX('BHP Site Access'!$G$3:$G$104,MATCH(LOWER(TRIM(INDEX('INPUT - Roster'!$D$1:$D$206,Grid!$B7)&"")&"|"&TRIM(INDEX('INPUT - Roster'!$E$1:$E$206,Grid!$B7)&"")),Calc!$AX$3:$AX$104,0))&""),"Not listed")) | T35: =IF(OR(Grid!$B7="",ISNUMBER(SEARCH("demob",E35))),"",IF(AND(UPPER(TRIM(J35&""))="YES",UPPER(TRIM(K35&""))="YES",UPPER(TRIM(L35&""))="YES",LEFT(UPPER(M35),14)="QUALS COMPLETE"),"","GAP")) | U35: =IF(Grid!$B7="",0,IF(AND(OR(Dashboard!$D$9="All",D35=Dashboard!$D$9),OR(Dashboard!$J$9="All",E35=Dashboard!$J$9)),1,0))
B36: =IF(Grid!$B8="","",6) | C36: =IF(Grid!$B8="","",TRIM(INDEX('INPUT - Roster'!$F$1:$F$206,Grid!$B8)&"")) | D36: =IF(Grid!$B8="","",TRIM(INDEX('INPUT - Roster'!$C$1:$C$206,Grid!$B8)&"")) | E36: =IF(Grid!$B8="","",INDEX(Index!$C$2:$C$202,MATCH(Grid!$B8,Index!$A$2:$A$202,0))) | F36: =IF(Grid!$B8="","",TRIM(INDEX('INPUT - Roster'!$H$1:$H$206,Grid!$B8)&"")) | G36: =IF(Grid!$B8="","",TRIM(INDEX('INPUT - Roster'!$G$1:$G$206,Grid!$B8)&"")) | H36: =IF(Grid!$B8="","",TRIM(INDEX('INPUT - Roster'!$R$1:$R$206,Grid!$B8)&"")) | I36: =IF(Grid!$B8="","",TRIM(INDEX('INPUT - Roster'!$O$1:$O$206,Grid!$B8)&"")) | J36: =IF(Grid!$B8="","",TRIM(INDEX('INPUT - Roster'!$J$1:$J$206,Grid!$B8)&"")) | K36: =IF(Grid!$B8="","",TRIM(INDEX('INPUT - Roster'!$K$1:$K$206,Grid!$B8)&"")) | L36: =IF(Grid!$B8="","",TRIM(INDEX('INPUT - Roster'!$L$1:$L$206,Grid!$B8)&"")) | M36: =IF(Grid!$B8="","",TRIM(INDEX('INPUT - Roster'!$M$1:$M$206,Grid!$B8)&"")) | N36: =Grid!F8 | O36: =Grid!AI8 | P36: =Grid!BL8 | Q36: =IF(Grid!$D8="","",INDEX(Grid!$F$2:$AG$2,Grid!$D8)) | R36: =IF(Grid!$D8="","",INDEX(Grid!$F8:$AG8,Grid!$D8)) | S36: =IF(Grid!$B8="","",IFERROR(TRIM(INDEX('BHP Site Access'!$G$3:$G$104,MATCH(LOWER(TRIM(INDEX('INPUT - Roster'!$D$1:$D$206,Grid!$B8)&"")&"|"&TRIM(INDEX('INPUT - Roster'!$E$1:$E$206,Grid!$B8)&"")),Calc!$AX$3:$AX$104,0))&""),"Not listed")) | T36: =IF(OR(Grid!$B8="",ISNUMBER(SEARCH("demob",E36))),"",IF(AND(UPPER(TRIM(J36&""))="YES",UPPER(TRIM(K36&""))="YES",UPPER(TRIM(L36&""))="YES",LEFT(UPPER(M36),14)="QUALS COMPLETE"),"","GAP")) | U36: =IF(Grid!$B8="",0,IF(AND(OR(Dashboard!$D$9="All",D36=Dashboard!$D$9),OR(Dashboard!$J$9="All",E36=Dashboard!$J$9)),1,0))
B37: =IF(Grid!$B9="","",7) | C37: =IF(Grid!$B9="","",TRIM(INDEX('INPUT - Roster'!$F$1:$F$206,Grid!$B9)&"")) | D37: =IF(Grid!$B9="","",TRIM(INDEX('INPUT - Roster'!$C$1:$C$206,Grid!$B9)&"")) | E37: =IF(Grid!$B9="","",INDEX(Index!$C$2:$C$202,MATCH(Grid!$B9,Index!$A$2:$A$202,0))) | F37: =IF(Grid!$B9="","",TRIM(INDEX('INPUT - Roster'!$H$1:$H$206,Grid!$B9)&"")) | G37: =IF(Grid!$B9="","",TRIM(INDEX('INPUT - Roster'!$G$1:$G$206,Grid!$B9)&"")) | H37: =IF(Grid!$B9="","",TRIM(INDEX('INPUT - Roster'!$R$1:$R$206,Grid!$B9)&"")) | I37: =IF(Grid!$B9="","",TRIM(INDEX('INPUT - Roster'!$O$1:$O$206,Grid!$B9)&"")) | J37: =IF(Grid!$B9="","",TRIM(INDEX('INPUT - Roster'!$J$1:$J$206,Grid!$B9)&"")) | K37: =IF(Grid!$B9="","",TRIM(INDEX('INPUT - Roster'!$K$1:$K$206,Grid!$B9)&"")) | L37: =IF(Grid!$B9="","",TRIM(INDEX('INPUT - Roster'!$L$1:$L$206,Grid!$B9)&"")) | M37: =IF(Grid!$B9="","",TRIM(INDEX('INPUT - Roster'!$M$1:$M$206,Grid!$B9)&"")) | N37: =Grid!F9 | O37: =Grid!AI9 | P37: =Grid!BL9 | Q37: =IF(Grid!$D9="","",INDEX(Grid!$F$2:$AG$2,Grid!$D9)) | R37: =IF(Grid!$D9="","",INDEX(Grid!$F9:$AG9,Grid!$D9)) | S37: =IF(Grid!$B9="","",IFERROR(TRIM(INDEX('BHP Site Access'!$G$3:$G$104,MATCH(LOWER(TRIM(INDEX('INPUT - Roster'!$D$1:$D$206,Grid!$B9)&"")&"|"&TRIM(INDEX('INPUT - Roster'!$E$1:$E$206,Grid!$B9)&"")),Calc!$AX$3:$AX$104,0))&""),"Not listed")) | T37: =IF(OR(Grid!$B9="",ISNUMBER(SEARCH("demob",E37))),"",IF(AND(UPPER(TRIM(J37&""))="YES",UPPER(TRIM(K37&""))="YES",UPPER(TRIM(L37&""))="YES",LEFT(UPPER(M37),14)="QUALS COMPLETE"),"","GAP")) | U37: =IF(Grid!$B9="",0,IF(AND(OR(Dashboard!$D$9="All",D37=Dashboard!$D$9),OR(Dashboard!$J$9="All",E37=Dashboard!$J$9)),1,0))
B38: =IF(Grid!$B10="","",8) | C38: =IF(Grid!$B10="","",TRIM(INDEX('INPUT - Roster'!$F$1:$F$206,Grid!$B10)&"")) | D38: =IF(Grid!$B10="","",TRIM(INDEX('INPUT - Roster'!$C$1:$C$206,Grid!$B10)&"")) | E38: =IF(Grid!$B10="","",INDEX(Index!$C$2:$C$202,MATCH(Grid!$B10,Index!$A$2:$A$202,0))) | F38: =IF(Grid!$B10="","",TRIM(INDEX('INPUT - Roster'!$H$1:$H$206,Grid!$B10)&"")) | G38: =IF(Grid!$B10="","",TRIM(INDEX('INPUT - Roster'!$G$1:$G$206,Grid!$B10)&"")) | H38: =IF(Grid!$B10="","",TRIM(INDEX('INPUT - Roster'!$R$1:$R$206,Grid!$B10)&"")) | I38: =IF(Grid!$B10="","",TRIM(INDEX('INPUT - Roster'!$O$1:$O$206,Grid!$B10)&"")) | J38: =IF(Grid!$B10="","",TRIM(INDEX('INPUT - Roster'!$J$1:$J$206,Grid!$B10)&"")) | K38: =IF(Grid!$B10="","",TRIM(INDEX('INPUT - Roster'!$K$1:$K$206,Grid!$B10)&"")) | L38: =IF(Grid!$B10="","",TRIM(INDEX('INPUT - Roster'!$L$1:$L$206,Grid!$B10)&"")) | M38: =IF(Grid!$B10="","",TRIM(INDEX('INPUT - Roster'!$M$1:$M$206,Grid!$B10)&"")) | N38: =Grid!F10 | O38: =Grid!AI10 | P38: =Grid!BL10 | Q38: =IF(Grid!$D10="","",INDEX(Grid!$F$2:$AG$2,Grid!$D10)) | R38: =IF(Grid!$D10="","",INDEX(Grid!$F10:$AG10,Grid!$D10)) | S38: =IF(Grid!$B10="","",IFERROR(TRIM(INDEX('BHP Site Access'!$G$3:$G$104,MATCH(LOWER(TRIM(INDEX('INPUT - Roster'!$D$1:$D$206,Grid!$B10)&"")&"|"&TRIM(INDEX('INPUT - Roster'!$E$1:$E$206,Grid!$B10)&"")),Calc!$AX$3:$AX$104,0))&""),"Not listed")) | T38: =IF(OR(Grid!$B10="",ISNUMBER(SEARCH("demob",E38))),"",IF(AND(UPPER(TRIM(J38&""))="YES",UPPER(TRIM(K38&""))="YES",UPPER(TRIM(L38&""))="YES",LEFT(UPPER(M38),14)="QUALS COMPLETE"),"","GAP")) | U38: =IF(Grid!$B10="",0,IF(AND(OR(Dashboard!$D$9="All",D38=Dashboard!$D$9),OR(Dashboard!$J$9="All",E38=Dashboard!$J$9)),1,0))
B39: =IF(Grid!$B11="","",9) | C39: =IF(Grid!$B11="","",TRIM(INDEX('INPUT - Roster'!$F$1:$F$206,Grid!$B11)&"")) | D39: =IF(Grid!$B11="","",TRIM(INDEX('INPUT - Roster'!$C$1:$C$206,Grid!$B11)&"")) | E39: =IF(Grid!$B11="","",INDEX(Index!$C$2:$C$202,MATCH(Grid!$B11,Index!$A$2:$A$202,0))) | F39: =IF(Grid!$B11="","",TRIM(INDEX('INPUT - Roster'!$H$1:$H$206,Grid!$B11)&"")) | G39: =IF(Grid!$B11="","",TRIM(INDEX('INPUT - Roster'!$G$1:$G$206,Grid!$B11)&"")) | H39: =IF(Grid!$B11="","",TRIM(INDEX('INPUT - Roster'!$R$1:$R$206,Grid!$B11)&"")) | I39: =IF(Grid!$B11="","",TRIM(INDEX('INPUT - Roster'!$O$1:$O$206,Grid!$B11)&"")) | J39: =IF(Grid!$B11="","",TRIM(INDEX('INPUT - Roster'!$J$1:$J$206,Grid!$B11)&"")) | K39: =IF(Grid!$B11="","",TRIM(INDEX('INPUT - Roster'!$K$1:$K$206,Grid!$B11)&"")) | L39: =IF(Grid!$B11="","",TRIM(INDEX('INPUT - Roster'!$L$1:$L$206,Grid!$B11)&"")) | M39: =IF(Grid!$B11="","",TRIM(INDEX('INPUT - Roster'!$M$1:$M$206,Grid!$B11)&"")) | N39: =Grid!F11 | O39: =Grid!AI11 | P39: =Grid!BL11 | Q39: =IF(Grid!$D11="","",INDEX(Grid!$F$2:$AG$2,Grid!$D11)) | R39: =IF(Grid!$D11="","",INDEX(Grid!$F11:$AG11,Grid!$D11)) | S39: =IF(Grid!$B11="","",IFERROR(TRIM(INDEX('BHP Site Access'!$G$3:$G$104,MATCH(LOWER(TRIM(INDEX('INPUT - Roster'!$D$1:$D$206,Grid!$B11)&"")&"|"&TRIM(INDEX('INPUT - Roster'!$E$1:$E$206,Grid!$B11)&"")),Calc!$AX$3:$AX$104,0))&""),"Not listed")) | T39: =IF(OR(Grid!$B11="",ISNUMBER(SEARCH("demob",E39))),"",IF(AND(UPPER(TRIM(J39&""))="YES",UPPER(TRIM(K39&""))="YES",UPPER(TRIM(L39&""))="YES",LEFT(UPPER(M39),14)="QUALS COMPLETE"),"","GAP")) | U39: =IF(Grid!$B11="",0,IF(AND(OR(Dashboard!$D$9="All",D39=Dashboard!$D$9),OR(Dashboard!$J$9="All",E39=Dashboard!$J$9)),1,0))
B40: =IF(Grid!$B12="","",10) | C40: =IF(Grid!$B12="","",TRIM(INDEX('INPUT - Roster'!$F$1:$F$206,Grid!$B12)&"")) | D40: =IF(Grid!$B12="","",TRIM(INDEX('INPUT - Roster'!$C$1:$C$206,Grid!$B12)&"")) | E40: =IF(Grid!$B12="","",INDEX(Index!$C$2:$C$202,MATCH(Grid!$B12,Index!$A$2:$A$202,0))) | F40: =IF(Grid!$B12="","",TRIM(INDEX('INPUT - Roster'!$H$1:$H$206,Grid!$B12)&"")) | G40: =IF(Grid!$B12="","",TRIM(INDEX('INPUT - Roster'!$G$1:$G$206,Grid!$B12)&"")) | H40: =IF(Grid!$B12="","",TRIM(INDEX('INPUT - Roster'!$R$1:$R$206,Grid!$B12)&"")) | I40: =IF(Grid!$B12="","",TRIM(INDEX('INPUT - Roster'!$O$1:$O$206,Grid!$B12)&"")) | J40: =IF(Grid!$B12="","",TRIM(INDEX('INPUT - Roster'!$J$1:$J$206,Grid!$B12)&"")) | K40: =IF(Grid!$B12="","",TRIM(INDEX('INPUT - Roster'!$K$1:$K$206,Grid!$B12)&"")) | L40: =IF(Grid!$B12="","",TRIM(INDEX('INPUT - Roster'!$L$1:$L$206,Grid!$B12)&"")) | M40: =IF(Grid!$B12="","",TRIM(INDEX('INPUT - Roster'!$M$1:$M$206,Grid!$B12)&"")) | N40: =Grid!F12 | O40: =Grid!AI12 | P40: =Grid!BL12 | Q40: =IF(Grid!$D12="","",INDEX(Grid!$F$2:$AG$2,Grid!$D12)) | R40: =IF(Grid!$D12="","",INDEX(Grid!$F12:$AG12,Grid!$D12)) | S40: =IF(Grid!$B12="","",IFERROR(TRIM(INDEX('BHP Site Access'!$G$3:$G$104,MATCH(LOWER(TRIM(INDEX('INPUT - Roster'!$D$1:$D$206,Grid!$B12)&"")&"|"&TRIM(INDEX('INPUT - Roster'!$E$1:$E$206,Grid!$B12)&"")),Calc!$AX$3:$AX$104,0))&""),"Not listed")) | T40: =IF(OR(Grid!$B12="",ISNUMBER(SEARCH("demob",E40))),"",IF(AND(UPPER(TRIM(J40&""))="YES",UPPER(TRIM(K40&""))="YES",UPPER(TRIM(L40&""))="YES",LEFT(UPPER(M40),14)="QUALS COMPLETE"),"","GAP")) | U40: =IF(Grid!$B12="",0,IF(AND(OR(Dashboard!$D$9="All",D40=Dashboard!$D$9),OR(Dashboard!$J$9="All",E40=Dashboard!$J$9)),1,0))
B41: =IF(Grid!$B13="","",11) | C41: =IF(Grid!$B13="","",TRIM(INDEX('INPUT - Roster'!$F$1:$F$206,Grid!$B13)&"")) | D41: =IF(Grid!$B13="","",TRIM(INDEX('INPUT - Roster'!$C$1:$C$206,Grid!$B13)&"")) | E41: =IF(Grid!$B13="","",INDEX(Index!$C$2:$C$202,MATCH(Grid!$B13,Index!$A$2:$A$202,0))) | F41: =IF(Grid!$B13="","",TRIM(INDEX('INPUT - Roster'!$H$1:$H$206,Grid!$B13)&"")) | G41: =IF(Grid!$B13="","",TRIM(INDEX('INPUT - Roster'!$G$1:$G$206,Grid!$B13)&"")) | H41: =IF(Grid!$B13="","",TRIM(INDEX('INPUT - Roster'!$R$1:$R$206,Grid!$B13)&"")) | I41: =IF(Grid!$B13="","",TRIM(INDEX('INPUT - Roster'!$O$1:$O$206,Grid!$B13)&"")) | J41: =IF(Grid!$B13="","",TRIM(INDEX('INPUT - Roster'!$J$1:$J$206,Grid!$B13)&"")) | K41: =IF(Grid!$B13="","",TRIM(INDEX('INPUT - Roster'!$K$1:$K$206,Grid!$B13)&"")) | L41: =IF(Grid!$B13="","",TRIM(INDEX('INPUT - Roster'!$L$1:$L$206,Grid!$B13)&"")) | M41: =IF(Grid!$B13="","",TRIM(INDEX('INPUT - Roster'!$M$1:$M$206,Grid!$B13)&"")) | N41: =Grid!F13 | O41: =Grid!AI13 | P41: =Grid!BL13 | Q41: =IF(Grid!$D13="","",INDEX(Grid!$F$2:$AG$2,Grid!$D13)) | R41: =IF(Grid!$D13="","",INDEX(Grid!$F13:$AG13,Grid!$D13)) | S41: =IF(Grid!$B13="","",IFERROR(TRIM(INDEX('BHP Site Access'!$G$3:$G$104,MATCH(LOWER(TRIM(INDEX('INPUT - Roster'!$D$1:$D$206,Grid!$B13)&"")&"|"&TRIM(INDEX('INPUT - Roster'!$E$1:$E$206,Grid!$B13)&"")),Calc!$AX$3:$AX$104,0))&""),"Not listed")) | T41: =IF(OR(Grid!$B13="",ISNUMBER(SEARCH("demob",E41))),"",IF(AND(UPPER(TRIM(J41&""))="YES",UPPER(TRIM(K41&""))="YES",UPPER(TRIM(L41&""))="YES",LEFT(UPPER(M41),14)="QUALS COMPLETE"),"","GAP")) | U41: =IF(Grid!$B13="",0,IF(AND(OR(Dashboard!$D$9="All",D41=Dashboard!$D$9),OR(Dashboard!$J$9="All",E41=Dashboard!$J$9)),1,0))
B42: =IF(Grid!$B14="","",12) | C42: =IF(Grid!$B14="","",TRIM(INDEX('INPUT - Roster'!$F$1:$F$206,Grid!$B14)&"")) | D42: =IF(Grid!$B14="","",TRIM(INDEX('INPUT - Roster'!$C$1:$C$206,Grid!$B14)&"")) | E42: =IF(Grid!$B14="","",INDEX(Index!$C$2:$C$202,MATCH(Grid!$B14,Index!$A$2:$A$202,0))) | F42: =IF(Grid!$B14="","",TRIM(INDEX('INPUT - Roster'!$H$1:$H$206,Grid!$B14)&"")) | G42: =IF(Grid!$B14="","",TRIM(INDEX('INPUT - Roster'!$G$1:$G$206,Grid!$B14)&"")) | H42: =IF(Grid!$B14="","",TRIM(INDEX('INPUT - Roster'!$R$1:$R$206,Grid!$B14)&"")) | I42: =IF(Grid!$B14="","",TRIM(INDEX('INPUT - Roster'!$O$1:$O$206,Grid!$B14)&"")) | J42: =IF(Grid!$B14="","",TRIM(INDEX('INPUT - Roster'!$J$1:$J$206,Grid!$B14)&"")) | K42: =IF(Grid!$B14="","",TRIM(INDEX('INPUT - Roster'!$K$1:$K$206,Grid!$B14)&"")) | L42: =IF(Grid!$B14="","",TRIM(INDEX('INPUT - Roster'!$L$1:$L$206,Grid!$B14)&"")) | M42: =IF(Grid!$B14="","",TRIM(INDEX('INPUT - Roster'!$M$1:$M$206,Grid!$B14)&"")) | N42: =Grid!F14 | O42: =Grid!AI14 | P42: =Grid!BL14 | Q42: =IF(Grid!$D14="","",INDEX(Grid!$F$2:$AG$2,Grid!$D14)) | R42: =IF(Grid!$D14="","",INDEX(Grid!$F14:$AG14,Grid!$D14)) | S42: =IF(Grid!$B14="","",IFERROR(TRIM(INDEX('BHP Site Access'!$G$3:$G$104,MATCH(LOWER(TRIM(INDEX('INPUT - Roster'!$D$1:$D$206,Grid!$B14)&"")&"|"&TRIM(INDEX('INPUT - Roster'!$E$1:$E$206,Grid!$B14)&"")),Calc!$AX$3:$AX$104,0))&""),"Not listed")) | T42: =IF(OR(Grid!$B14="",ISNUMBER(SEARCH("demob",E42))),"",IF(AND(UPPER(TRIM(J42&""))="YES",UPPER(TRIM(K42&""))="YES",UPPER(TRIM(L42&""))="YES",LEFT(UPPER(M42),14)="QUALS COMPLETE"),"","GAP")) | U42: =IF(Grid!$B14="",0,IF(AND(OR(Dashboard!$D$9="All",D42=Dashboard!$D$9),OR(Dashboard!$J$9="All",E42=Dashboard!$J$9)),1,0))
B43: =IF(Grid!$B15="","",13) | C43: =IF(Grid!$B15="","",TRIM(INDEX('INPUT - Roster'!$F$1:$F$206,Grid!$B15)&"")) | D43: =IF(Grid!$B15="","",TRIM(INDEX('INPUT - Roster'!$C$1:$C$206,Grid!$B15)&"")) | E43: =IF(Grid!$B15="","",INDEX(Index!$C$2:$C$202,MATCH(Grid!$B15,Index!$A$2:$A$202,0))) | F43: =IF(Grid!$B15="","",TRIM(INDEX('INPUT - Roster'!$H$1:$H$206,Grid!$B15)&"")) | G43: =IF(Grid!$B15="","",TRIM(INDEX('INPUT - Roster'!$G$1:$G$206,Grid!$B15)&"")) | H43: =IF(Grid!$B15="","",TRIM(INDEX('INPUT - Roster'!$R$1:$R$206,Grid!$B15)&"")) | I43: =IF(Grid!$B15="","",TRIM(INDEX('INPUT - Roster'!$O$1:$O$206,Grid!$B15)&"")) | J43: =IF(Grid!$B15="","",TRIM(INDEX('INPUT - Roster'!$J$1:$J$206,Grid!$B15)&"")) | K43: =IF(Grid!$B15="","",TRIM(INDEX('INPUT - Roster'!$K$1:$K$206,Grid!$B15)&"")) | L43: =IF(Grid!$B15="","",TRIM(INDEX('INPUT - Roster'!$L$1:$L$206,Grid!$B15)&"")) | M43: =IF(Grid!$B15="","",TRIM(INDEX('INPUT - Roster'!$M$1:$M$206,Grid!$B15)&"")) | N43: =Grid!F15 | O43: =Grid!AI15 | P43: =Grid!BL15 | Q43: =IF(Grid!$D15="","",INDEX(Grid!$F$2:$AG$2,Grid!$D15)) | R43: =IF(Grid!$D15="","",INDEX(Grid!$F15:$AG15,Grid!$D15)) | S43: =IF(Grid!$B15="","",IFERROR(TRIM(INDEX('BHP Site Access'!$G$3:$G$104,MATCH(LOWER(TRIM(INDEX('INPUT - Roster'!$D$1:$D$206,Grid!$B15)&"")&"|"&TRIM(INDEX('INPUT - Roster'!$E$1:$E$206,Grid!$B15)&"")),Calc!$AX$3:$AX$104,0))&""),"Not listed")) | T43: =IF(OR(Grid!$B15="",ISNUMBER(SEARCH("demob",E43))),"",IF(AND(UPPER(TRIM(J43&""))="YES",UPPER(TRIM(K43&""))="YES",UPPER(TRIM(L43&""))="YES",LEFT(UPPER(M43),14)="QUALS COMPLETE"),"","GAP")) | U43: =IF(Grid!$B15="",0,IF(AND(OR(Dashboard!$D$9="All",D43=Dashboard!$D$9),OR(Dashboard!$J$9="All",E43=Dashboard!$J$9)),1,0))
...

Sheet Camp Summary
B1: Camp & Travel Summary - 21 Aug 2026 to 31 Dec 2027
B2: Counts every person on the INPUT roster for each day. Beds = camp code in the cell (arrival days included). Today is highlighted red.
C3: =UPPER(TEXT(C4,"ddd")) | D3: =UPPER(TEXT(D4,"ddd")) | E3: =UPPER(TEXT(E4,"ddd")) | F3: =UPPER(TEXT(F4,"ddd")) | G3: =UPPER(TEXT(G4,"ddd")) | H3: =UPPER(TEXT(H4,"ddd")) | I3: =UPPER(TEXT(I4,"ddd")) | J3: =UPPER(TEXT(J4,"ddd")) | ... SF3: =UPPER(TEXT(SF4,"ddd"))
B4: Camp / movement | C4: ='INPUT - Roster'!S4 | D4: ='INPUT - Roster'!T4 | E4: ='INPUT - Roster'!U4 | F4: ='INPUT - Roster'!V4 | G4: ='INPUT - Roster'!W4 | H4: ='INPUT - Roster'!X4 | I4: ='INPUT - Roster'!Y4 | J4: ='INPUT - Roster'!Z4 | ... SF4: ='INPUT - Roster'!SV4
B5: BEDS BY CAMP
